Workbook
Name CASE: [1]LBO!$E$7
Name CASE: 'Operating Model'!#REF!
Name CIRC: [1]LBO!$E$6
Name CIRC: 'Operating Model'!#REF!
Name PIK: [1]LBO!$E$8
Name tgr: 'Operating Model'!$L$11
Name wacc: 'Operating Model'!$L$10

Sheet Cover
B2: Cover
A4: x | B4: Simple DCF Tutorial | H4: Amazon Advanced DCF - Part 1 | N4: Amazon Advanced DCF - Part 2 | T4: Amazon Advanced DCF - Part 3
B5: https://youtu.be/nyot7FkYoqM | H5: https://youtube.com/live/fmoE3H8RjP4 | N5: https://youtube.com/live/z9S9QNosrA4 | T5: https://youtube.com/live/Jh_oUKy4bPk
B6: - DCF Concepts | H6: - Revenue Build | N6: - Gather Historical Cash Flow Items | T6: - Trading Comps
B7: - Projecting FCF | H7: - EBIT Build | N7: - Sum-of-the-parts DCF | T7: - Terminal Value - Perpetuity and Exit Multiple
B8: - Terminal Value | H8: - Project FCF | N8: - Projections for Revenue and EBIT | T8: - Levering / Unlevering Beta
B9: - Discounting to Present Value | H9: - WACC | N9: - Multiple Scenarios | T9: - Convertible bonds
H10: - Mid-Year Convention | T10: - Sensitivity Tables
H11: - Terminal Value
H12: - Diluted Shares
A14: x | B14: Notes
B15: Get 1:1 help to break into investment banking | I15: https://www.bankingaccelerator.com/
B16: Lots of free resources + sign up for my free weekly finance newsletter | I16: https://www.rareliquid.com/
B18: Investment Banking Videos | I18: https://www.youtube.com/watch?v=hQfLWritg9s&list=PL71QplJWp1RoobXOSA77YooScaVYmPojv
B19: Modeling Tutorial Videos | I19: https://www.youtube.com/playlist?list=PL71QplJWp1RoaKEMTo_9CZA-kyjwT5rGo
A21: x | B21: rareliquid (the guy who created this model)
B22: YouTube | I22: https://www.youtube.com/@rareliquid
B23: Instagram | I23: https://www.instagram.com/rareliquid
B24: TikTok | I24: https://www.tiktok.com/@rareliquid
B25: LinkedIn | I25: https://www.linkedin.com/in/benchon

Sheet Operating Model
B2: Operating Model
A4: x | B4: Ticker | L4: AMZN
B5: Date | L5: 45596
B6: End of Year | L6: 45657
A8: x | B8: Assumptions
B10: WACC | L10: =WACC!F22 -> 0.083315111
B11: TGR | L11: 0.025
A13: x | B13: Financials
A15: x | B15: Revenue | C15: 2015 | D15: =C15+1 -> 2016 | E15: =D15+1 -> 2017 | F15: =E15+1 -> 2018 | G15: =F15+1 -> 2019 | H15: =G15+1 -> 2020 | I15: =H15+1 -> 2021 | J15: =I15+1 -> 2022 | K15: =J15+1 -> 2023 | ... Q15: =P15+1 -> 2029
B17: North America | C17: =Segments!C6 -> 63708 | D17: =Segments!D6 -> 79785 | E17: =Segments!E6 -> 106110 | F17: =Segments!F6 -> 141366 | G17: =Segments!G6 -> 170773 | H17: =Segments!H6 -> 236282 | I17: =Segments!I6 -> 279833 | J17: =Segments!J6 -> 315880 | ... Q17: =Segments!Q6 -> 590847
B18: % growth | C18: =IF(ISERROR(C17/B17-1),"--",C17/B17-1) -> -- | D18: =IF(ISERROR(D17/C17-1),"--",D17/C17-1) -> 0.25235449 | E18: =IF(ISERROR(E17/D17-1),"--",E17/D17-1) -> 0.32994924 | F18: =IF(ISERROR(F17/E17-1),"--",F17/E17-1) -> 0.33225898 | G18: =IF(ISERROR(G17/F17-1),"--",G17/F17-1) -> 0.20802032 | H18: =IF(ISERROR(H17/G17-1),"--",H17/G17-1) -> 0.38360279 | I18: =IF(ISERROR(I17/H17-1),"--",I17/H17-1) -> 0.18431789 | J18: =IF(ISERROR(J17/I17-1),"--",J17/I17-1) -> 0.12881612 | ... Q18: =IF(ISERROR(Q17/P17-1),"--",Q17/P17-1) -> 0.08153123
B19: % of total sales | C19: =C17/C$29 -> 0.59536848 | D19: =D17/D$29 -> 0.58671049 | E19: =E17/E$29 -> 0.5965727 | F19: =F17/F$29 -> 0.60701542 | G19: =G17/G$29 -> 0.60876865 | H19: =H17/H$29 -> 0.61202806 | I19: =I17/I$29 -> 0.59561494 | J19: =J17/J$29 -> 0.61457286 | ... Q19: =Q17/Q$29 -> 0.55955871
B21: International | C21: =Segments!C8 -> 35418 | D21: =Segments!D8 -> 43983 | E21: =Segments!E8 -> 54297 | F21: =Segments!F8 -> 65866 | G21: =Segments!G8 -> 74723 | H21: =Segments!H8 -> 104412 | I21: =Segments!I8 -> 127787 | J21: =Segments!J8 -> 118007 | ... Q21: =Segments!Q8 -> 215930
B22: % growth | C22: =IF(ISERROR(C21/B21-1),"--",C21/B21-1) -> -- | D22: =IF(ISERROR(D21/C21-1),"--",D21/C21-1) -> 0.24182619 | E22: =IF(ISERROR(E21/D21-1),"--",E21/D21-1) -> 0.23449969 | F22: =IF(ISERROR(F21/E21-1),"--",F21/E21-1) -> 0.21306886 | G22: =IF(ISERROR(G21/F21-1),"--",G21/F21-1) -> 0.13446998 | H22: =IF(ISERROR(H21/G21-1),"--",H21/G21-1) -> 0.39732077 | I22: =IF(ISERROR(I21/H21-1),"--",I21/H21-1) -> 0.22387273 | J22: =IF(ISERROR(J21/I21-1),"--",J21/I21-1) -> -0.076533607 | ... Q22: =IF(ISERROR(Q21/P21-1),"--",Q21/P21-1) -> 0.08281181
B23: % of total sales | C23: =C21/C$29 -> 0.33099079 | D23: =D21/D$29 -> 0.32343533 | E23: =E21/E$29 -> 0.30526914 | F23: =F21/F$29 -> 0.28282386 | G23: =G21/G$29 -> 0.26637126 | H23: =H21/H$29 -> 0.27045257 | I23: =I21/I$29 -> 0.27199024 | J23: =J21/J$29 -> 0.2295932 | ... Q23: =Q21/Q$29 -> 0.20449543
B25: AWS | C25: =Segments!C9 -> 7880 | D25: =Segments!D9 -> 12219 | E25: =Segments!E9 -> 17459 | F25: =Segments!F9 -> 25655 | G25: =Segments!G9 -> 35026 | H25: =Segments!H9 -> 45370 | I25: =Segments!I9 -> 62202 | J25: =Segments!J9 -> 80096 | ... Q25: =Segments!Q9 -> 249139
B26: % growth | C26: =IF(ISERROR(C25/B25-1),"--",C25/B25-1) -> -- | D26: =IF(ISERROR(D25/C25-1),"--",D25/C25-1) -> 0.55063452 | E26: =IF(ISERROR(E25/D25-1),"--",E25/D25-1) -> 0.42884033 | F26: =IF(ISERROR(F25/E25-1),"--",F25/E25-1) -> 0.46944269 | G26: =IF(ISERROR(G25/F25-1),"--",G25/F25-1) -> 0.36526993 | H26: =IF(ISERROR(H25/G25-1),"--",H25/G25-1) -> 0.29532347 | I26: =IF(ISERROR(I25/H25-1),"--",I25/H25-1) -> 0.37099405 | J26: =IF(ISERROR(J25/I25-1),"--",J25/I25-1) -> 0.28767564 | ... Q26: =IF(ISERROR(Q25/P25-1),"--",Q25/P25-1) -> 0.19362891
B27: % of total sales | C27: =C25/C$29 -> 0.07364073 | D27: =D25/D$29 -> 0.089854177 | E27: =E25/E$29 -> 0.098158164 | F27: =F25/F$29 -> 0.11016072 | G27: =G25/G$29 -> 0.12486008 | H27: =H25/H$29 -> 0.11751938 | I27: =I25/I$29 -> 0.13239482 | J27: =J25/J$29 -> 0.15583395 | ... Q27: =Q25/Q$29 -> 0.23594585
B29: Total | C29: =C17+C21+C25 -> 107006 | D29: =D17+D21+D25 -> 135987 | E29: =E17+E21+E25 -> 177866 | F29: =F17+F21+F25 -> 232887 | G29: =G17+G21+G25 -> 280522 | H29: =H17+H21+H25 -> 386064 | I29: =I17+I21+I25 -> 469822 | J29: =J17+J21+J25 -> 513983 | ... Q29: =Q17+Q21+Q25 -> 1055916
B30: % growth | C30: =IF(ISERROR(C29/B29-1),"--",C29/B29-1) -> -- | D30: =IF(ISERROR(D29/C29-1),"--",D29/C29-1) -> 0.27083528 | E30: =IF(ISERROR(E29/D29-1),"--",E29/D29-1) -> 0.30796326 | F30: =IF(ISERROR(F29/E29-1),"--",F29/E29-1) -> 0.30933962 | G30: =IF(ISERROR(G29/F29-1),"--",G29/F29-1) -> 0.20454126 | H30: =IF(ISERROR(H29/G29-1),"--",H29/G29-1) -> 0.37623431 | I30: =IF(ISERROR(I29/H29-1),"--",I29/H29-1) -> 0.21695367 | J30: =IF(ISERROR(J29/I29-1),"--",J29/I29-1) -> 0.093995173 | ... Q30: =IF(ISERROR(Q29/P29-1),"--",Q29/P29-1) -> 0.10631298
A32: x | B32: EBIT | C32: 2015 | D32: 2016 | E32: 2017 | F32: 2018 | G32: 2019 | H32: 2020 | I32: 2021 | J32: 2022 | K32: 2023 | L32: 2024 | M32: 2025 | N32: 2026 | O32: 2027 | P32: 2028 | Q32: 2029
B34: North America | C34: =Segments!C12 -> 2751 | D34: =Segments!D12 -> 4099 | E34: =Segments!E12 -> 2837 | F34: =Segments!F12 -> 7267 | G34: =Segments!G12 -> 7033 | H34: =Segments!H12 -> 8651 | I34: =Segments!I12 -> 7271 | J34: =Segments!J12 -> -2847 | ... N34: =Segments!N12 -> 34190 | O34: =O35*O17 -> 36853.135 | P34: =P35*P17 -> 40475.354 | Q34: =Q35*Q17 -> 43775.36
B35: % of sales | C35: =C34/C17 -> 0.04318139 | D35: =D34/D17 -> 0.051375572 | E35: =E34/E17 -> 0.026736406 | F35: =F34/F17 -> 0.051405571 | G35: =G34/G17 -> 0.041183325 | H35: =H34/H17 -> 0.03661303 | I35: =I34/I17 -> 0.025983354 | J35: =J34/J17 -> -0.0090129163 | ... N35: =N34/N17 -> 0.074089163 | O35: =N35 -> 0.074089163 | P35: =O35 -> 0.074089163 | Q35: =P35 -> 0.074089163
B36: % of total EBIT | C36: =C34/C$46 -> 0.60822463 | D36: =D34/D$46 -> 0.55936135 | E36: =E34/E$46 -> 0.69094009 | F36: =F34/F$46 -> 0.58505756 | G36: =G34/G$46 -> 0.48366687 | H36: =H34/H$46 -> 0.37778942 | I36: =I34/I$46 -> 0.29225451 | J36: =J34/J$46 -> -0.23244611 | ... Q36: =Q34/Q$46 -> 0.27652694
B38: International | C38: =Segments!C14 -> -91 | D38: =Segments!D14 -> -477 | E38: =Segments!E14 -> -3062 | F38: =Segments!F14 -> -2142 | G38: =Segments!G14 -> -1693 | H38: =Segments!H14 -> 717 | I38: =Segments!I14 -> -924 | J38: =Segments!J14 -> -7746 | ... N38: =Segments!N14 -> 9726 | O38: =O39*O21 -> 10911.071 | P38: =P39*P21 -> 11295.389 | Q38: =Q39*Q21 -> 12230.781
B39: % of sales | C39: =C38/C21 -> -0.002569315 | D39: =D38/D21 -> -0.010845099 | E39: =E38/E21 -> -0.056393539 | F39: =F38/F21 -> -0.032520572 | G39: =G38/G21 -> -0.022657013 | H39: =H38/H21 -> 0.0068670268 | I39: =I38/I21 -> -0.0072307825 | J39: =J38/J21 -> -0.065640174 | ... N39: =N38/N21 -> 0.056642343 | O39: =N39 -> 0.056642343 | P39: =O39 -> 0.056642343 | Q39: =P39 -> 0.056642343
B40: % of total EBIT | C40: =C38/C$46 -> -0.02011939 | D40: =D38/D$46 -> -0.065092795 | E40: =E38/E$46 -> -0.74573794 | F40: =F38/F$46 -> -0.17244988 | G40: =G38/G$46 -> -0.11642941 | H40: =H38/H$46 -> 0.031311411 | I40: =I38/I$46 -> -0.037139756 | J40: =J38/J$46 -> -0.63242978 | ... Q40: =Q38/Q$46 -> 0.077261283
B42: AWS | C42: =Segments!C15 -> 1863 | D42: =Segments!D15 -> 3706 | E42: =Segments!E15 -> 4331 | F42: =Segments!F15 -> 7296 | G42: =Segments!G15 -> 9201 | H42: =Segments!H15 -> 13531 | I42: =Segments!I15 -> 18532 | J42: =Segments!J15 -> 22841 | ... Q42: =Segments!Q15 -> 102298
B43: % of sales | C43: =C42/C25 -> 0.23642132 | D43: =D42/D25 -> 0.30329814 | E43: =E42/E25 -> 0.2480669 | F43: =F42/F25 -> 0.28438901 | G43: =G42/G25 -> 0.26269057 | H43: =H42/H25 -> 0.29823672 | I43: =I42/I25 -> 0.29793254 | J43: =J42/J25 -> 0.2851703 | ... Q43: =Q42/Q25 -> 0.41060613
B44: % of total EBIT | C44: =C42/C$46 -> 0.41189476 | D44: =D42/D$46 -> 0.50573144 | E44: =E42/E$46 -> 1.0547979 | F44: =F42/F$46 -> 0.58739232 | G44: =G42/G$46 -> 0.63276253 | H44: =H42/H$46 -> 0.59089917 | I44: =I42/I$46 -> 0.74488524 | J44: =J42/J$46 -> 1.8648759 | ... Q44: =Q42/Q$46 -> 0.64621178
B46: Total | C46: =C34+C38+C42 -> 4523 | D46: =D34+D38+D42 -> 7328 | E46: =E34+E38+E42 -> 4106 | F46: =F34+F38+F42 -> 12421 | G46: =G34+G38+G42 -> 14541 | H46: =H34+H38+H42 -> 22899 | I46: =I34+I38+I42 -> 24879 | J46: =J34+J38+J42 -> 12248 | ... Q46: =Q34+Q38+Q42 -> 158304.14
B47: % of sales | C47: =C46/C29 -> 0.042268658 | D47: =D46/D29 -> 0.053887504 | E47: =E46/E29 -> 0.023084794 | F47: =F46/F29 -> 0.053334879 | G47: =G46/G29 -> 0.051835507 | H47: =H46/H29 -> 0.059314 | I47: =I46/I29 -> 0.052954098 | J47: =J46/J29 -> 0.023829582 | ... Q47: =Q46/Q29 -> 0.14992115
A49: x | B49: Tax Rate | C49: 2015 | D49: 2016 | E49: 2017 | F49: 2018 | G49: 2019 | H49: 2020 | I49: 2021 | J49: 2022 | K49: 2023 | L49: 2024 | M49: 2025 | N49: 2026 | O49: 2027 | P49: 2028 | Q49: 2029
B51: Taxes | C51: =IS!C31 -> 950 | D51: =IS!D31 -> 1425 | E51: =IS!E31 -> 769 | F51: =IS!F31 -> 1197 | G51: =IS!G31 -> 2374 | H51: =IS!H31 -> 2863 | I51: =IS!I31 -> 4791 | J51: =IS!J31 -> -3217 | ... L51: =IS!L31 -> 9602
B52: % tax rate | C52: =IF(C51<0,"--",IS!C31/IS!C30) -> 0.60586735 | D52: =IF(D51<0,"--",IS!D31/IS!D30) -> 0.36613566 | E52: =IF(E51<0,"--",IS!E31/IS!E30) -> 0.2020494 | F52: =IF(F51<0,"--",IS!F31/IS!F30) -> 0.10629607 | G52: =IF(G51<0,"--",IS!G31/IS!G30) -> 0.16986262 | H52: =IF(H51<0,"--",IS!H31/IS!H30) -> 0.11841343 | I52: =IF(I51<0,"--",IS!I31/IS!I30) -> 0.12557993 | J52: =IF(J51<0,"--",IS!J31/IS!J30) -> -- | ... L52: =IF(L51<0,"--",IS!L31/IS!L30) -> 0.1774763 | M52: =AVERAGE(H52:L52) -> 0.15276204 | N52: =AVERAGE(I52:M52) -> 0.16134919 | O52: =AVERAGE(J52:N52) -> 0.17029151 | P52: =AVERAGE(K52:O52) -> 0.17029151 | Q52: =AVERAGE(L52:P52) -> 0.16643411
A54: x | B54: D&A | C54: 2015 | D54: =C54+1 -> 2016 | E54: =D54+1 -> 2017 | F54: =E54+1 -> 2018 | G54: =F54+1 -> 2019 | H54: =G54+1 -> 2020 | I54: =H54+1 -> 2021 | J54: =I54+1 -> 2022 | K54: =J54+1 -> 2023 | ... Q54: =P54+1 -> 2029
B56: North America | I56: =I58*I$75 -> 13823.793 | J56: =J58*J$75 -> 19451.788 | K56: =K58*K$75 -> 22021.919 | L56: =L59*L$17 -> 22347.588 | M56: =M59*M$17 -> 25660.827 | N56: =N59*N$17 -> 27813.124 | O56: =O59*O$17 -> 29623.918 | P56: =P59*P$17 -> 32855.58 | Q56: =Q59*Q$17 -> 35444.428
B57: North America (Partial) | I57: 9234 | J57: 11565 | K57: 13678
B58: % of total D&A | I58: =I57/I$73 -> 0.40307303 | J58: =J57/J$73 -> 0.46401059 | K58: =K57/K$73 -> 0.45253929
B59: % of North America sales | I59: =I56/I17 -> 0.049400151 | J59: =J56/J17 -> 0.061579676 | K59: =K56/K17 -> 0.062415453 | L59: =AVERAGE(I59:K59) -> 0.057798427 | M59: =AVERAGE(J59:L59) -> 0.060597852 | N59: =AVERAGE(K59:M59) -> 0.060270577 | O59: =AVERAGE(L59:N59) -> 0.059555619 | P59: =AVERAGE(M59:O59) -> 0.060141349 | Q59: =AVERAGE(N59:P59) -> 0.059989182
...

Sheet DCF>>>

Sheet Consolidated
B2: Consolidated DCF
B4: Assumptions
B5: WACC | D5: ='Operating Model'!L10 -> 0.083315111
B6: TGR | D6: ='Operating Model'!L11 -> 0.025
A8: x | B8: Consolidated DCF
A10: x | B10: 12/31 FYE | C10: 2021 | D10: =C10+1 -> 2022 | E10: =D10+1 -> 2023 | F10: =E10+1 -> 2024 | G10: =F10+1 -> 2025 | H10: =G10+1 -> 2026 | I10: =H10+1 -> 2027 | J10: =I10+1 -> 2028 | K10: =J10+1 -> 2029
B12: Revenue | C12: ='North America'!C12+International!C12+AWS!C12 -> 469822 | D12: ='North America'!D12+International!D12+AWS!D12 -> 513983 | E12: ='North America'!E12+International!E12+AWS!E12 -> 574785 | F12: ='North America'!F12+International!F12+AWS!F12 -> 635646 | G12: ='North America'!G12+International!G12+AWS!G12 -> 705769 | H12: ='North America'!H12+International!H12+AWS!H12 -> 784827 | I12: ='North America'!I12+International!I12+AWS!I12 -> 866627 | J12: ='North America'!J12+International!J12+AWS!J12 -> 954446 | K12: ='North America'!K12+International!K12+AWS!K12 -> 1055916
B13: % growth | D13: =D12/C12-1 -> 0.093995173 | E13: =E12/D12-1 -> 0.11829574 | F13: =F12/E12-1 -> 0.10588481 | G13: =G12/F12-1 -> 0.11031769 | H13: =H12/G12-1 -> 0.11201682 | I13: =I12/H12-1 -> 0.10422679 | J13: =J12/I12-1 -> 0.10133425 | K13: =K12/J12-1 -> 0.10631298
B15: EBIT | C15: ='North America'!C15+International!C15+AWS!C15 -> 24879 | D15: ='North America'!D15+International!D15+AWS!D15 -> 12248 | E15: ='North America'!E15+International!E15+AWS!E15 -> 36852 | F15: ='North America'!F15+International!F15+AWS!F15 -> 62270.17 | G15: ='North America'!G15+International!G15+AWS!G15 -> 77775.41 | H15: ='North America'!H15+International!H15+AWS!H15 -> 97823.1 | I15: ='North America'!I15+International!I15+AWS!I15 -> 118182.71 | J15: ='North America'!J15+International!J15+AWS!J15 -> 136838.24 | K15: ='North America'!K15+International!K15+AWS!K15 -> 158304.14
B16: % of sales | C16: =C15/C12 -> 0.052954098 | D16: =D15/D12 -> 0.023829582 | E16: =E15/E12 -> 0.064114408 | F16: =F15/F12 -> 0.097963599 | G16: =G15/G12 -> 0.11019953 | H16: =H15/H12 -> 0.12464288 | I16: =I15/I12 -> 0.1363709 | J16: =J15/J12 -> 0.14336929 | K16: =K15/K12 -> 0.14992115
B18: Taxes | F18: ='North America'!F18+International!F18+AWS!F18 -> 11051.479 | G18: ='North America'!G18+International!G18+AWS!G18 -> 11881.13 | H18: ='North America'!H18+International!H18+AWS!H18 -> 15783.678 | I18: ='North America'!I18+International!I18+AWS!I18 -> 20125.511 | J18: ='North America'!J18+International!J18+AWS!J18 -> 23302.391 | K18: ='North America'!K18+International!K18+AWS!K18 -> 26347.209
B19: % tax rate | F19: ='Operating Model'!L52 -> 0.1774763 | G19: ='Operating Model'!M52 -> 0.15276204 | H19: ='Operating Model'!N52 -> 0.16134919 | I19: ='Operating Model'!O52 -> 0.17029151 | J19: ='Operating Model'!P52 -> 0.17029151 | K19: ='Operating Model'!Q52 -> 0.16643411
B21: EBIAT | F21: ='North America'!F21+International!F21+AWS!F21 -> 51218.691 | G21: ='North America'!G21+International!G21+AWS!G21 -> 65894.28 | H21: ='North America'!H21+International!H21+AWS!H21 -> 82039.422 | I21: ='North America'!I21+International!I21+AWS!I21 -> 98057.195 | J21: ='North America'!J21+International!J21+AWS!J21 -> 113535.85 | K21: ='North America'!K21+International!K21+AWS!K21 -> 131956.93
B23: D&A | F23: ='North America'!F23+International!F23+AWS!F23 -> 53278.041 | G23: ='North America'!G23+International!G23+AWS!G23 -> 61079.38 | H23: ='North America'!H23+International!H23+AWS!H23 -> 69829.088 | I23: ='North America'!I23+International!I23+AWS!I23 -> 78145.767 | J23: ='North America'!J23+International!J23+AWS!J23 -> 88681.083 | K23: ='North America'!K23+International!K23+AWS!K23 -> 101224.35
B24: % of sales | F24: =F23/F$12 -> 0.083817157 | G24: =G23/G$12 -> 0.086543019 | H24: =H23/H$12 -> 0.088973861 | I24: =I23/I$12 -> 0.09017232 | J24: =J23/J$12 -> 0.092913673 | K24: =K23/K$12 -> 0.095864017
B26: CapEx | F26: ='North America'!F26+International!F26+AWS!F26 -> 76711.639 | G26: ='North America'!G26+International!G26+AWS!G26 -> 83017.381 | H26: ='North America'!H26+International!H26+AWS!H26 -> 91194.885 | I26: ='North America'!I26+International!I26+AWS!I26 -> 107386.31 | J26: ='North America'!J26+International!J26+AWS!J26 -> 120577.76 | K26: ='North America'!K26+International!K26+AWS!K26 -> 137639.54
B27: % of sales | F27: =F26/F$12 -> 0.12068296 | G27: =G26/G$12 -> 0.11762685 | H27: =H26/H$12 -> 0.11619744 | I27: =I26/I$12 -> 0.12391296 | J27: =J26/J$12 -> 0.12633272 | K27: =K26/K$12 -> 0.13035084
B29: Change in NWC | F29: ='North America'!F29+International!F29+AWS!F29 -> -21708.527 | G29: ='North America'!G29+International!G29+AWS!G29 -> -22317.9 | H29: ='North America'!H29+International!H29+AWS!H29 -> -22459.872 | I29: ='North America'!I29+International!I29+AWS!I29 -> -27267.444 | J29: ='North America'!J29+International!J29+AWS!J29 -> -29175.374 | K29: ='North America'!K29+International!K29+AWS!K29 -> -31906.032
B30: % of sales | F30: =F29/F$12 -> -0.034151913 | G30: =G29/G$12 -> -0.031622103 | H30: =H29/H$12 -> -0.028617609 | I30: =I29/I$12 -> -0.031463875 | J30: =J29/J$12 -> -0.030567863 | K30: =K29/K$12 -> -0.030216449
B32: Unlevered FCF | F32: ='North America'!F32+International!F32+AWS!F32 -> 49493.62 | G32: ='North America'!G32+International!G32+AWS!G32 -> 66274.179 | H32: ='North America'!H32+International!H32+AWS!H32 -> 83133.497 | I32: ='North America'!I32+International!I32+AWS!I32 -> 96084.092 | J32: ='North America'!J32+International!J32+AWS!J32 -> 110814.55 | K32: ='North America'!K32+International!K32+AWS!K32 -> 127447.78
A33: x | B33: PV of UFCF | F33: ='North America'!F33+International!F33+AWS!F33 -> 8194.109 | G33: ='North America'!G33+International!G33+AWS!G33 -> 62831.075 | H33: ='North America'!H33+International!H33+AWS!H33 -> 72753.08 | I33: ='North America'!I33+International!I33+AWS!I33 -> 77619.711 | J33: ='North America'!J33+International!J33+AWS!J33 -> 82634.71 | K33: ='North America'!K33+International!K33+AWS!K33 -> 87729.003
B35: Stub | F35: =YEARFRAC('Operating Model'!L5,'Operating Model'!L6) -> 0.16666667
B36: Discount Period | F36: =F35/2 -> 0.083333333 | G36: =F35+0.5 -> 0.66666667 | H36: =G36+1 -> 1.6666667 | I36: =H36+1 -> 2.6666667 | J36: =I36+1 -> 3.6666667 | K36: =J36+1 -> 4.6666667
B38: Terminal Value | K38: ='North America'!K38+International!K38+AWS!K38 -> 2800429.5
B39: PV of Terminal Value | K39: ='North America'!K39+International!K39+AWS!K39 -> 1927682.8
B41: Enterprise Value | K41: ='North America'!K41+International!K41+AWS!K41 -> 2319444.5
B42: (+) Cash | K42: =71178+17914 -> 89092
B43: (-) Debt | K43: 54889
B44: Equity Value | K44: =K41+K42-K43 -> 2353647.5
B46: FDSO | K46: =Shares!E14 -> 10876.067
A47: x | B47: Implied Share Price | K47: =K44/K46 -> 216.40613
M49: Sensitivity Table
O51: WACC
N52: =K47 -> 216.40613 | O52: =P52+0.25% -> 0.088315111 | P52: =Q52+0.25% -> 0.085815111 | Q52: 0.083315111 | R52: =Q52-0.25% -> 0.080815111 | S52: =R52-0.25% -> 0.078315111
N53: =N54-0.25% -> 0.02 | O53: =('North America'!O59+International!O59+AWS!O59+$K$42-$K$43)/$K$46 -> 195.47074 | P53: =('North America'!P59+International!P59+AWS!P59+$K$42-$K$43)/$K$46 -> 201.00914 | Q53: =('North America'!Q59+International!Q59+AWS!Q59+$K$42-$K$43)/$K$46 -> 206.93945 | R53: =('North America'!R59+International!R59+AWS!R59+$K$42-$K$43)/$K$46 -> 213.30901 | S53: =('North America'!S59+International!S59+AWS!S59+$K$42-$K$43)/$K$46 -> 220.17327
N54: =N55-0.25% -> 0.0225 | O54: =('North America'!O60+International!O60+AWS!O60+$K$42-$K$43)/$K$46 -> 199.29266 | P54: =('North America'!P60+International!P60+AWS!P60+$K$42-$K$43)/$K$46 -> 205.16779 | Q54: =('North America'!Q60+International!Q60+AWS!Q60+$K$42-$K$43)/$K$46 -> 211.47821 | R54: =('North America'!R60+International!R60+AWS!R60+$K$42-$K$43)/$K$46 -> 218.27885 | S54: =('North America'!S60+International!S60+AWS!S60+$K$42-$K$43)/$K$46 -> 225.63449
M55: TGR | N55: 0.025 | O55: =('North America'!O61+International!O61+AWS!O61+$K$42-$K$43)/$K$46 -> 203.41639 | P55: =('North America'!P61+International!P61+AWS!P61+$K$42-$K$43)/$K$46 -> 209.66836 | Q55: =('North America'!Q61+International!Q61+AWS!Q61+$K$42-$K$43)/$K$46 -> 216.40613 | R55: =('North America'!R61+International!R61+AWS!R61+$K$42-$K$43)/$K$46 -> 223.6939 | S55: =('North America'!S61+International!S61+AWS!S61+$K$42-$K$43)/$K$46 -> 231.60788
N56: =N55+0.25% -> 0.0275 | O56: =('North America'!O62+International!O62+AWS!O62+$K$42-$K$43)/$K$46 -> 207.87916 | P56: =('North America'!P62+International!P62+AWS!P62+$K$42-$K$43)/$K$46 -> 214.5548 | Q56: =('North America'!Q62+International!Q62+AWS!Q62+$K$42-$K$43)/$K$46 -> 221.77549 | R56: =('North America'!R62+International!R62+AWS!R62+$K$42-$K$43)/$K$46 -> 229.61678 | S56: =('North America'!S62+International!S62+AWS!S62+$K$42-$K$43)/$K$46 -> 238.16903
N57: =N56+0.25% -> 0.03 | O57: =('North America'!O63+International!O63+AWS!O63+$K$42-$K$43)/$K$46 -> 212.72457 | P57: =('North America'!P63+International!P63+AWS!P63+$K$42-$K$43)/$K$46 -> 219.87898 | Q57: =('North America'!Q63+International!Q63+AWS!Q63+$K$42-$K$43)/$K$46 -> 227.64841 | R57: =('North America'!R63+International!R63+AWS!R63+$K$42-$K$43)/$K$46 -> 236.12245 | S57: =('North America'!S63+International!S63+AWS!S63+$K$42-$K$43)/$K$46 -> 245.40917

Sheet North America
B2: North America DCF
B4: Assumptions
B5: WACC | D5: ='Operating Model'!L10 -> 0.083315111
B6: TGR | D6: ='Operating Model'!L11 -> 0.025
A8: x | B8: North America DCF
A10: x | B10: 12/31 FYE | C10: 2021 | D10: =C10+1 -> 2022 | E10: =D10+1 -> 2023 | F10: =E10+1 -> 2024 | G10: =F10+1 -> 2025 | H10: =G10+1 -> 2026 | I10: =H10+1 -> 2027 | J10: =I10+1 -> 2028 | K10: =J10+1 -> 2029
B12: Revenue | C12: ='Operating Model'!I17 -> 279833 | D12: ='Operating Model'!J17 -> 315880 | E12: ='Operating Model'!K17 -> 352828 | F12: ='Operating Model'!L17 -> 386647 | G12: ='Operating Model'!M17 -> 423461 | H12: ='Operating Model'!N17 -> 461471 | I12: ='Operating Model'!O17 -> 497416 | J12: ='Operating Model'!P17 -> 546306 | K12: ='Operating Model'!Q17 -> 590847
B13: % growth | C13: ='Operating Model'!I18 -> 0.18431789 | D13: ='Operating Model'!J18 -> 0.12881612 | E13: ='Operating Model'!K18 -> 0.11696847 | F13: ='Operating Model'!L18 -> 0.095851236 | G13: ='Operating Model'!M18 -> 0.095213463 | H13: ='Operating Model'!N18 -> 0.089760332 | I13: ='Operating Model'!O18 -> 0.077892219 | J13: ='Operating Model'!P18 -> 0.098287952 | K13: ='Operating Model'!Q18 -> 0.08153123
B15: EBIT | C15: ='Operating Model'!I34 -> 7271 | D15: ='Operating Model'!J34 -> -2847 | E15: ='Operating Model'!K34 -> 14877 | F15: ='Operating Model'!L34 -> 23233.5 | G15: ='Operating Model'!M34 -> 31059.3 | H15: ='Operating Model'!N34 -> 34190 | I15: ='Operating Model'!O34 -> 36853.135 | J15: ='Operating Model'!P34 -> 40475.354 | K15: ='Operating Model'!Q34 -> 43775.36
B16: % of sales | C16: ='Operating Model'!I35 -> 0.025983354 | D16: ='Operating Model'!J35 -> -0.0090129163 | E16: ='Operating Model'!K35 -> 0.042165021 | F16: ='Operating Model'!L35 -> 0.060089694 | G16: ='Operating Model'!M35 -> 0.073346306 | H16: ='Operating Model'!N35 -> 0.074089163 | I16: ='Operating Model'!O35 -> 0.074089163 | J16: ='Operating Model'!P35 -> 0.074089163 | K16: ='Operating Model'!Q35 -> 0.074089163
B18: Taxes | F18: =F19*F15 -> 4123.3955 | G18: =G19*G15 -> 4744.6821 | H18: =H19*H15 -> 5516.529 | I18: =I19*I15 -> 6275.776 | J18: =J19*J15 -> 6892.6092 | K18: =K19*K15 -> 7285.713
B19: % tax rate | F19: ='Operating Model'!L52 -> 0.1774763 | G19: ='Operating Model'!M52 -> 0.15276204 | H19: ='Operating Model'!N52 -> 0.16134919 | I19: ='Operating Model'!O52 -> 0.17029151 | J19: ='Operating Model'!P52 -> 0.17029151 | K19: ='Operating Model'!Q52 -> 0.16643411
B21: EBIAT | F21: =F15-F18 -> 19110.104 | G21: =G15-G18 -> 26314.618 | H21: =H15-H18 -> 28673.471 | I21: =I15-I18 -> 30577.359 | J21: =J15-J18 -> 33582.745 | K21: =K15-K18 -> 36489.647
B23: D&A | C23: ='Operating Model'!I56 -> 13823.793 | D23: ='Operating Model'!J56 -> 19451.788 | E23: ='Operating Model'!K56 -> 22021.919 | F23: ='Operating Model'!L56 -> 22347.588 | G23: ='Operating Model'!M56 -> 25660.827 | H23: ='Operating Model'!N56 -> 27813.124 | I23: ='Operating Model'!O56 -> 29623.918 | J23: ='Operating Model'!P56 -> 32855.58 | K23: ='Operating Model'!Q56 -> 35444.428
B24: % of sales | C24: ='Operating Model'!I59 -> 0.049400151 | D24: ='Operating Model'!J59 -> 0.061579676 | E24: ='Operating Model'!K59 -> 0.062415453 | F24: ='Operating Model'!L59 -> 0.057798427 | G24: ='Operating Model'!M59 -> 0.060597852 | H24: ='Operating Model'!N59 -> 0.060270577 | I24: ='Operating Model'!O59 -> 0.059555619 | J24: ='Operating Model'!P59 -> 0.060141349 | K24: ='Operating Model'!Q59 -> 0.059989182
B26: CapEx | C26: ='Operating Model'!I81 -> 32756.109 | D26: ='Operating Model'!J81 -> 25920.769 | E26: ='Operating Model'!K81 -> 19870.295 | F26: ='Operating Model'!L81 -> 32920.68 | G26: ='Operating Model'!M81 -> 31550.69 | H26: ='Operating Model'!N81 -> 33220.985 | I26: ='Operating Model'!O81 -> 38407.158 | J26: ='Operating Model'!P81 -> 40737.929 | K26: ='Operating Model'!Q81 -> 44071.765
B27: % of sales | C27: ='Operating Model'!I84 -> 0.11705592 | D27: ='Operating Model'!J84 -> 0.082058912 | E27: ='Operating Model'!K84 -> 0.056317228 | F27: ='Operating Model'!L84 -> 0.085144019 | G27: ='Operating Model'!M84 -> 0.07450672 | H27: ='Operating Model'!N84 -> 0.071989323 | I27: ='Operating Model'!O84 -> 0.077213354 | J27: ='Operating Model'!P84 -> 0.074569799 | K27: ='Operating Model'!Q84 -> 0.074590825
B29: Change in NWC | C29: ='Operating Model'!I105 -> -11680.604 | D29: ='Operating Model'!J105 -> -12835.969 | E29: ='Operating Model'!K105 -> -7084.3671 | F29: ='Operating Model'!L105 -> -13204.735 | G29: ='Operating Model'!M105 -> -13390.727 | H29: ='Operating Model'!N105 -> -13206.197 | I29: ='Operating Model'!O105 -> -15650.635 | J29: ='Operating Model'!P105 -> -16699.407 | K29: ='Operating Model'!Q105 -> -17853.298
B30: % of sales | C30: ='Operating Model'!I106 -> -0.04174134 | D30: ='Operating Model'!J106 -> -0.040635585 | E30: ='Operating Model'!K106 -> -0.020078812 | F30: ='Operating Model'!L106 -> -0.034151913 | G30: ='Operating Model'!M106 -> -0.031622103 | H30: ='Operating Model'!N106 -> -0.028617609 | I30: ='Operating Model'!O106 -> -0.031463875 | J30: ='Operating Model'!P106 -> -0.030567863 | K30: ='Operating Model'!Q106 -> -0.030216449
B32: Unlevered FCF | F32: =F21+F23-F26-F29 -> 21741.748 | G32: =G21+G23-G26-G29 -> 33815.482 | H32: =H21+H23-H26-H29 -> 36471.807 | I32: =I21+I23-I26-I29 -> 37444.754 | J32: =J21+J23-J26-J29 -> 42399.803 | K32: =K21+K23-K26-K29 -> 45715.607
A33: x | B33: PV of UFCF | F33: =(F32*F35)/(1+$D$5)^F36 -> 3599.5397 | G33: =G32/(1+$D$5)^G36 -> 32058.686 | H33: =H32/(1+$D$5)^H36 -> 31917.775 | I33: =I32/(1+$D$5)^I36 -> 30249.034 | J33: =J32/(1+$D$5)^J36 -> 31617.649 | K33: =K32/(1+$D$5)^K36 -> 31468.455
B35: Stub | F35: =Consolidated!F35 -> 0.16666667
B36: Discount Period | F36: =Consolidated!F36 -> 0.083333333 | G36: =Consolidated!G36 -> 0.66666667 | H36: =Consolidated!H36 -> 1.6666667 | I36: =Consolidated!I36 -> 2.6666667 | J36: =Consolidated!J36 -> 3.6666667 | K36: =Consolidated!K36 -> 4.6666667
B38: Terminal Value | K38: =C49 -> 950615.74
A39: x | B39: PV of Terminal Value | K39: =C50 -> 654358.78
B41: Enterprise Value | K41: =SUM(F33:K33,K39) -> 815269.91
A43: x | B43: Terminal Value
B45: Enterprise Value | E45: Perpetuity Growth | I45: Exit Multiple
B46: % Perpetuity | C46: 0.8 | E46: Terminal Growth Rate | G46: =D6 -> 0.025 | I46: Terminal Year EBITDA | K46: =K15+K23 -> 79219.788
B47: % Exit Multiple | C47: =1-C46 -> 0.2 | E47: Terminal Value | G47: =(K32*(1+G46))/(D5-G46) -> 803539.55 | I47: EBITDA multiple | K47: =Comps!AC22 -> 19.425961
E48: PV of Terminal Value | G48: =G47/(1+D5)^K36 -> 553118.5 | I48: Terminal Value | K48: =K46*K47 -> 1538920.5
B49: Total Terminal Value | C49: =C46*G47+C47*K48 -> 950615.74 | E49: Total Enterprise Value (TEV) | G49: =SUM(F33:K33)+G48 -> 714029.64 | I49: PV of Terminal Value | K49: =K48/(1+$D$5)^K36 -> 1059319.9
B50: PV of Terminal Value | C50: =C46*G48+C47*K49 -> 654358.78 | I50: Total Enterprise Value (TEV) | K50: =SUM(F33:K33)+K49 -> 1220231
E52: Terminal Value as % of TEV | G52: =G48/G49 -> 0.77464361 | I52: Terminal Value as % of TEV | K52: =K49/K50 -> 0.86813059
A53: x | E53: Implied TV Exit EBITDA Multiple | G53: =G49/(K15+K23) -> 9.0132739 | I53: Implied terminal growth rate | K53: =(($D$5-(K32/K48))/((1+(K32/K48)))) -> 0.052062252
M55: Sensitivity Table
O57: WACC
N58: =K41 -> 815269.91 | O58: =P58+0.25% -> 0.088315111 | P58: =Q58+0.25% -> 0.085815111 | Q58: 0.083315111 | R58: =Q58-0.25% -> 0.080815111 | S58: =R58-0.25% -> 0.078315111
N59: =N60-0.25% -> 0.02 | O59: 734248.09 | P59: 755530.91 | Q59: 778338.01 | R59: 802854.02 | S59: 829295.2
N60: =N61-0.25% -> 0.0225 | O60: 749158.34 | P60: 771754.86 | Q60: 796044.86 | R60: 822242.64 | S60: 850600.82
...

Sheet International
B2: International DCF
B4: Assumptions
B5: WACC | D5: ='Operating Model'!L10 -> 0.083315111
B6: TGR | D6: ='Operating Model'!L11 -> 0.025
A8: x | B8: International DCF
A10: x | B10: 12/31 FYE | C10: 2021 | D10: =C10+1 -> 2022 | E10: =D10+1 -> 2023 | F10: =E10+1 -> 2024 | G10: =F10+1 -> 2025 | H10: =G10+1 -> 2026 | I10: =H10+1 -> 2027 | J10: =I10+1 -> 2028 | K10: =J10+1 -> 2029
B12: Revenue | C12: ='Operating Model'!I21 -> 127787 | D12: ='Operating Model'!J21 -> 118007 | E12: ='Operating Model'!K21 -> 131200 | F12: ='Operating Model'!L21 -> 141444 | G12: ='Operating Model'!M21 -> 154680 | H12: ='Operating Model'!N21 -> 171709 | I12: ='Operating Model'!O21 -> 192631 | J12: ='Operating Model'!P21 -> 199416 | K12: ='Operating Model'!Q21 -> 215930
B13: % growth | C13: ='Operating Model'!I22 -> 0.22387273 | D13: ='Operating Model'!J22 -> -0.076533607 | E13: ='Operating Model'!K22 -> 0.11179845 | F13: ='Operating Model'!L22 -> 0.078079268 | G13: ='Operating Model'!M22 -> 0.09357767 | H13: ='Operating Model'!N22 -> 0.1100918 | I13: ='Operating Model'!O22 -> 0.12184568 | J13: ='Operating Model'!P22 -> 0.035222783 | K13: ='Operating Model'!Q22 -> 0.08281181
B15: EBIT | C15: ='Operating Model'!I38 -> -924 | D15: ='Operating Model'!J38 -> -7746 | E15: ='Operating Model'!K38 -> -2656 | F15: ='Operating Model'!L38 -> 1765.17 | G15: ='Operating Model'!M38 -> 3899.91 | H15: ='Operating Model'!N38 -> 9726 | I15: ='Operating Model'!O38 -> 10911.071 | J15: ='Operating Model'!P38 -> 11295.389 | K15: ='Operating Model'!Q38 -> 12230.781
B16: % of sales | C16: ='Operating Model'!I39 -> -0.0072307825 | D16: ='Operating Model'!J39 -> -0.065640174 | E16: ='Operating Model'!K39 -> -0.020243902 | F16: ='Operating Model'!L39 -> 0.012479639 | G16: ='Operating Model'!M39 -> 0.025212762 | H16: ='Operating Model'!N39 -> 0.056642343 | I16: ='Operating Model'!O39 -> 0.056642343 | J16: ='Operating Model'!P39 -> 0.056642343 | K16: ='Operating Model'!Q39 -> 0.056642343
B18: Taxes | F18: =F19*F15 -> 313.27583 | G18: =G19*G15 -> 595.75822 | H18: =H19*H15 -> 1569.2823 | I18: =I19*I15 -> 1858.0628 | J18: =J19*J15 -> 1923.5089 | K18: =K19*K15 -> 2035.6192
B19: % tax rate | F19: ='Operating Model'!L52 -> 0.1774763 | G19: ='Operating Model'!M52 -> 0.15276204 | H19: ='Operating Model'!N52 -> 0.16134919 | I19: ='Operating Model'!O52 -> 0.17029151 | J19: ='Operating Model'!P52 -> 0.17029151 | K19: ='Operating Model'!Q52 -> 0.16643411
B21: EBIAT | F21: =F15-F18 -> 1451.8942 | G21: =G15-G18 -> 3304.1518 | H21: =H15-H18 -> 8156.7177 | I21: =I15-I18 -> 9053.0083 | J21: =J15-J18 -> 9371.8805 | K21: =K15-K18 -> 10195.162
B23: D&A | C23: ='Operating Model'!I61 -> 4524.0959 | D23: ='Operating Model'!J61 -> 5858.2428 | E23: ='Operating Model'!K61 -> 6465.8597 | F23: ='Operating Model'!L61 -> 6333.3465 | G23: ='Operating Model'!M61 -> 7409.2751 | H23: ='Operating Model'!N61 -> 8125.2405 | I23: ='Operating Model'!O61 -> 8989.2443 | J23: ='Operating Model'!P61 -> 9431.4536 | K23: ='Operating Model'!Q61 -> 10168.922
B24: % of sales | C24: ='Operating Model'!I64 -> 0.035403412 | D24: ='Operating Model'!J64 -> 0.04964318 | E24: ='Operating Model'!K64 -> 0.049282467 | F24: ='Operating Model'!L64 -> 0.044776353 | G24: ='Operating Model'!M64 -> 0.047900667 | H24: ='Operating Model'!N64 -> 0.047319829 | I24: ='Operating Model'!O64 -> 0.046665616 | J24: ='Operating Model'!P64 -> 0.047295371 | K24: ='Operating Model'!Q64 -> 0.047093605
B26: CapEx | C26: ='Operating Model'!I86 -> 8985.879 | D26: ='Operating Model'!J86 -> 7345.4219 | E26: ='Operating Model'!K86 -> 4697.5014 | F26: ='Operating Model'!L86 -> 7938.2601 | G26: ='Operating Model'!M86 -> 7949.1476 | H26: ='Operating Model'!N86 -> 8202.9989 | I26: ='Operating Model'!O86 -> 9971.0036 | J26: ='Operating Model'!P86 -> 10032.34 | K26: ='Operating Model'!Q86 -> 10785.234
B27: % of sales | C27: ='Operating Model'!I89 -> 0.070319196 | D27: ='Operating Model'!J89 -> 0.062245646 | E27: ='Operating Model'!K89 -> 0.035804127 | F27: ='Operating Model'!L89 -> 0.056122989 | G27: ='Operating Model'!M89 -> 0.051390921 | H27: ='Operating Model'!N89 -> 0.047772679 | I27: ='Operating Model'!O89 -> 0.051762196 | J27: ='Operating Model'!P89 -> 0.050308599 | K27: ='Operating Model'!Q89 -> 0.049947825
B29: Change in NWC | C29: ='Operating Model'!I109 -> -5334.0007 | D29: ='Operating Model'!J109 -> -4795.2835 | E29: ='Operating Model'!K109 -> -2634.3401 | F29: ='Operating Model'!L109 -> -4830.5831 | G29: ='Operating Model'!M109 -> -4891.3069 | H29: ='Operating Model'!N109 -> -4913.9011 | I29: ='Operating Model'!O109 -> -6060.9177 | J29: ='Operating Model'!P109 -> -6095.7209 | K29: ='Operating Model'!Q109 -> -6524.6378
B30: % of sales | C30: ='Operating Model'!I110 -> -0.04174134 | D30: ='Operating Model'!J110 -> -0.040635585 | E30: ='Operating Model'!K110 -> -0.020078812 | F30: ='Operating Model'!L110 -> -0.034151913 | G30: ='Operating Model'!M110 -> -0.031622103 | H30: ='Operating Model'!N110 -> -0.028617609 | I30: ='Operating Model'!O110 -> -0.031463875 | J30: ='Operating Model'!P110 -> -0.030567863 | K30: ='Operating Model'!Q110 -> -0.030216449
B32: Unlevered FCF | F32: =F21+F23-F26-F29 -> 4677.5637 | G32: =G21+G23-G26-G29 -> 7655.5862 | H32: =H21+H23-H26-H29 -> 12992.86 | I32: =I21+I23-I26-I29 -> 14132.167 | J32: =J21+J23-J26-J29 -> 14866.715 | K32: =K21+K23-K26-K29 -> 16103.488
A33: x | B33: PV of UFCF | F33: =(F32*F35)/(1+$D$5)^F36 -> 774.41227 | G33: =G32/(1+$D$5)^G36 -> 7257.86 | H33: =H32/(1+$D$5)^H36 -> 11370.514 | I33: =I32/(1+$D$5)^I36 -> 11416.403 | J33: =J32/(1+$D$5)^J36 -> 11086.15 | K33: =K32/(1+$D$5)^K36 -> 11084.877
B35: Stub | F35: =Consolidated!F35 -> 0.16666667
B36: Discount Period | F36: =Consolidated!F36 -> 0.083333333 | G36: =Consolidated!G36 -> 0.66666667 | H36: =Consolidated!H36 -> 1.6666667 | I36: =Consolidated!I36 -> 2.6666667 | J36: =Consolidated!J36 -> 3.6666667 | K36: =Consolidated!K36 -> 4.6666667
B38: Terminal Value | K38: =C49 -> 313466.92
A39: x | B39: PV of Terminal Value | K39: =C50 -> 215775.76
B41: Enterprise Value | K41: =SUM(F33:K33,K39) -> 268765.97
A43: x | B43: Terminal Value
B45: Enterprise Value | E45: Perpetuity Growth | I45: Exit Multiple
B46: % Perpetuity | C46: 0.8 | E46: Terminal Growth Rate | G46: =D6 -> 0.025 | I46: Terminal Year EBITDA | K46: =K15+K23 -> 22399.703
B47: % Exit Multiple | C47: =1-C46 -> 0.2 | E47: Terminal Value | G47: =(K32*(1+G46))/(D5-G46) -> 283049.71 | I47: EBITDA multiple | K47: =Comps!AC22 -> 19.425961
E48: PV of Terminal Value | G48: =G47/(1+D5)^K36 -> 194837.99 | I48: Terminal Value | K48: =K46*K47 -> 435135.76
B49: Total Terminal Value | C49: =C46*G47+C47*K48 -> 313466.92 | E49: Total Enterprise Value (TEV) | G49: =SUM(F33:K33)+G48 -> 247828.21 | I49: PV of Terminal Value | K49: =K48/(1+$D$5)^K36 -> 299526.82
B50: PV of Terminal Value | C50: =C46*G48+C47*K49 -> 215775.76 | I50: Total Enterprise Value (TEV) | K50: =SUM(F33:K33)+K49 -> 352517.03
E52: Terminal Value as % of TEV | G52: =G48/G49 -> 0.78618166 | I52: Terminal Value as % of TEV | K52: =K49/K50 -> 0.84968041
A53: x | E53: Implied TV Exit EBITDA Multiple | G53: =G49/(K15+K23) -> 11.063906 | I53: Implied terminal growth rate | K53: =(($D$5-(K32/K48))/((1+(K32/K48)))) -> 0.044654573
M55: Sensitivity Table
O57: WACC
N58: =K41 -> 268765.97 | O58: =P58+0.25% -> 0.088315111 | P58: =Q58+0.25% -> 0.085815111 | Q58: 0.083315111 | R58: =Q58-0.25% -> 0.080815111 | S58: =R58-0.25% -> 0.078315111
N59: =N60-0.25% -> 0.02 | O59: 240541.94 | P59: 247881.81 | Q59: 255756.58 | R59: 264231.26 | S59: 273382
N60: =N61-0.25% -> 0.0225 | O60: 245794.13 | P60: 253596.75 | Q60: 261993.88 | R60: 271060.97 | S60: 280886.98
...

Sheet AWS
B2: AWS DCF
B4: Assumptions
B5: WACC | D5: ='Operating Model'!L10 -> 0.083315111
B6: TGR | D6: ='Operating Model'!L11 -> 0.025
A8: x | B8: AWS DCF
A10: x | B10: 12/31 FYE | C10: 2021 | D10: =C10+1 -> 2022 | E10: =D10+1 -> 2023 | F10: =E10+1 -> 2024 | G10: =F10+1 -> 2025 | H10: =G10+1 -> 2026 | I10: =H10+1 -> 2027 | J10: =I10+1 -> 2028 | K10: =J10+1 -> 2029
B12: Revenue | C12: ='Operating Model'!I25 -> 62202 | D12: ='Operating Model'!J25 -> 80096 | E12: ='Operating Model'!K25 -> 90757 | F12: ='Operating Model'!L25 -> 107555 | G12: ='Operating Model'!M25 -> 127628 | H12: ='Operating Model'!N25 -> 151647 | I12: ='Operating Model'!O25 -> 176580 | J12: ='Operating Model'!P25 -> 208724 | K12: ='Operating Model'!Q25 -> 249139
B13: % growth | C13: ='Operating Model'!I26 -> 0.37099405 | D13: ='Operating Model'!J26 -> 0.28767564 | E13: ='Operating Model'!K26 -> 0.13310278 | F13: ='Operating Model'!L26 -> 0.18508765 | G13: ='Operating Model'!M26 -> 0.1866301 | H13: ='Operating Model'!N26 -> 0.18819538 | I13: ='Operating Model'!O26 -> 0.16441473 | J13: ='Operating Model'!P26 -> 0.18203647 | K13: ='Operating Model'!Q26 -> 0.19362891
B15: EBIT | C15: ='Operating Model'!I42 -> 18532 | D15: ='Operating Model'!J42 -> 22841 | E15: ='Operating Model'!K42 -> 24631 | F15: ='Operating Model'!L42 -> 37271.5 | G15: ='Operating Model'!M42 -> 42816.2 | H15: ='Operating Model'!N42 -> 53907.1 | I15: ='Operating Model'!O42 -> 70418.5 | J15: ='Operating Model'!P42 -> 85067.5 | K15: ='Operating Model'!Q42 -> 102298
B16: % of sales | C16: ='Operating Model'!I43 -> 0.29793254 | D16: ='Operating Model'!J43 -> 0.2851703 | E16: ='Operating Model'!K43 -> 0.27139504 | F16: ='Operating Model'!L43 -> 0.34653433 | G16: ='Operating Model'!M43 -> 0.33547654 | H16: ='Operating Model'!N43 -> 0.35547752 | I16: ='Operating Model'!O43 -> 0.39879092 | J16: ='Operating Model'!P43 -> 0.40755974 | K16: ='Operating Model'!Q43 -> 0.41060613
B18: Taxes | F18: =F19*F15 -> 6614.8077 | G18: =G19*G15 -> 6540.6901 | H18: =H19*H15 -> 8697.8672 | I18: =I19*I15 -> 11991.673 | J18: =J19*J15 -> 14486.273 | K18: =K19*K15 -> 17025.877
B19: % tax rate | F19: ='Operating Model'!L52 -> 0.1774763 | G19: ='Operating Model'!M52 -> 0.15276204 | H19: ='Operating Model'!N52 -> 0.16134919 | I19: ='Operating Model'!O52 -> 0.17029151 | J19: ='Operating Model'!P52 -> 0.17029151 | K19: ='Operating Model'!Q52 -> 0.16643411
B21: EBIAT | F21: =F15-F18 -> 30656.692 | G21: =G15-G18 -> 36275.51 | H21: =H15-H18 -> 45209.233 | I21: =I15-I18 -> 58426.827 | J21: =J15-J18 -> 70581.227 | K21: =K15-K18 -> 85272.123
B23: D&A | C23: ='Operating Model'!I66 -> 15948.112 | D23: ='Operating Model'!J66 -> 16610.969 | E23: ='Operating Model'!K66 -> 20175.221 | F23: ='Operating Model'!L66 -> 24597.106 | G23: ='Operating Model'!M66 -> 28009.278 | H23: ='Operating Model'!N66 -> 33890.724 | I23: ='Operating Model'!O66 -> 39532.605 | J23: ='Operating Model'!P66 -> 46394.05 | K23: ='Operating Model'!Q66 -> 55610.999
B24: % of sales | C24: ='Operating Model'!I69 -> 0.25639226 | D24: ='Operating Model'!J69 -> 0.20738825 | E24: ='Operating Model'!K69 -> 0.22229934 | F24: ='Operating Model'!L69 -> 0.22869328 | G24: ='Operating Model'!M69 -> 0.21946029 | H24: ='Operating Model'!N69 -> 0.2234843 | I24: ='Operating Model'!O69 -> 0.22387929 | J24: ='Operating Model'!P69 -> 0.22227463 | K24: ='Operating Model'!Q69 -> 0.22321274
B26: CapEx | C26: ='Operating Model'!I91 -> 19311.012 | D26: ='Operating Model'!J91 -> 30378.809 | E26: ='Operating Model'!K91 -> 28161.204 | F26: ='Operating Model'!L91 -> 35852.699 | G26: ='Operating Model'!M91 -> 43517.543 | H26: ='Operating Model'!N91 -> 49770.901 | I26: ='Operating Model'!O91 -> 59008.152 | J26: ='Operating Model'!P91 -> 69807.494 | K26: ='Operating Model'!Q91 -> 82782.537
B27: % of sales | C27: ='Operating Model'!I94 -> 0.31045645 | D27: ='Operating Model'!J94 -> 0.37927997 | E27: ='Operating Model'!K94 -> 0.31029236 | F27: ='Operating Model'!L94 -> 0.33334293 | G27: ='Operating Model'!M94 -> 0.34097175 | H27: ='Operating Model'!N94 -> 0.32820235 | I27: ='Operating Model'!O94 -> 0.33417234 | J27: ='Operating Model'!P94 -> 0.33444881 | K27: ='Operating Model'!Q94 -> 0.3322745
B29: Change in NWC | C29: ='Operating Model'!I113 -> -2596.3949 | D29: ='Operating Model'!J113 -> -3254.7478 | E29: ='Operating Model'!K113 -> -1822.2927 | F29: ='Operating Model'!L113 -> -3673.209 | G29: ='Operating Model'!M113 -> -4035.8658 | H29: ='Operating Model'!N113 -> -4339.7746 | I29: ='Operating Model'!O113 -> -5555.8911 | J29: ='Operating Model'!P113 -> -6380.2465 | K29: ='Operating Model'!Q113 -> -7528.0959
B30: % of sales | C30: ='Operating Model'!I114 -> -0.04174134 | D30: ='Operating Model'!J114 -> -0.040635585 | E30: ='Operating Model'!K114 -> -0.020078812 | F30: ='Operating Model'!L114 -> -0.034151913 | G30: ='Operating Model'!M114 -> -0.031622103 | H30: ='Operating Model'!N114 -> -0.028617609 | I30: ='Operating Model'!O114 -> -0.031463875 | J30: ='Operating Model'!P114 -> -0.030567863 | K30: ='Operating Model'!Q114 -> -0.030216449
B32: Unlevered FCF | F32: =F21+F23-F26-F29 -> 23074.309 | G32: =G21+G23-G26-G29 -> 24803.11 | H32: =H21+H23-H26-H29 -> 33668.83 | I32: =I21+I23-I26-I29 -> 44507.171 | J32: =J21+J23-J26-J29 -> 53548.029 | K32: =K21+K23-K26-K29 -> 65628.681
A33: x | B33: PV of UFCF | F33: =(F32*F35)/(1+$D$5)^F36 -> 3820.157 | G33: =G32/(1+$D$5)^G36 -> 23514.529 | H33: =H32/(1+$D$5)^H36 -> 29464.791 | I33: =I32/(1+$D$5)^I36 -> 35954.274 | J33: =J32/(1+$D$5)^J36 -> 39930.911 | K33: =K32/(1+$D$5)^K36 -> 45175.67
B35: Stub | F35: =Consolidated!F35 -> 0.16666667
B36: Discount Period | F36: =Consolidated!F36 -> 0.083333333 | G36: =Consolidated!G36 -> 0.66666667 | H36: =Consolidated!H36 -> 1.6666667 | I36: =Consolidated!I36 -> 2.6666667 | J36: =Consolidated!J36 -> 3.6666667 | K36: =Consolidated!K36 -> 4.6666667
B38: Terminal Value | K38: =C49 -> 1536346.9
A39: x | B39: PV of Terminal Value | K39: =C50 -> 1057548.3
B41: Enterprise Value | K41: =SUM(F33:K33,K39) -> 1235408.6
A43: x | B43: Terminal Value
B45: Enterprise Value | E45: Perpetuity Growth | I45: Exit Multiple
B46: % Perpetuity | C46: 0.8 | E46: Terminal Growth Rate | G46: =D6 -> 0.025 | I46: Terminal Year EBITDA | K46: =K15+K23 -> 157909
B47: % Exit Multiple | C47: =1-C46 -> 0.2 | E47: Terminal Value | G47: =(K32*(1+G46))/(D5-G46) -> 1153550 | I47: EBITDA multiple | K47: =Comps!AC22 -> 19.425961
E48: PV of Terminal Value | G48: =G47/(1+D5)^K36 -> 794049.12 | I48: Terminal Value | K48: =K46*K47 -> 3067534.1
B49: Total Terminal Value | C49: =C46*G47+C47*K48 -> 1536346.9 | E49: Total Enterprise Value (TEV) | G49: =SUM(F33:K33)+G48 -> 971909.45 | I49: PV of Terminal Value | K49: =K48/(1+$D$5)^K36 -> 2111544.9
B50: PV of Terminal Value | C50: =C46*G48+C47*K49 -> 1057548.3 | I50: Total Enterprise Value (TEV) | K50: =SUM(F33:K33)+K49 -> 2289405.3
E52: Terminal Value as % of TEV | G52: =G48/G49 -> 0.81699907 | I52: Terminal Value as % of TEV | K52: =K49/K50 -> 0.92231156
A53: x | E53: Implied TV Exit EBITDA Multiple | G53: =G49/(K15+K23) -> 6.1548706 | I53: Implied terminal growth rate | K53: =(($D$5-(K32/K48))/((1+(K32/K48)))) -> 0.06062349
M55: Sensitivity Table
O57: WACC
N58: =K41 -> 1235408.6 | O58: =P58+0.25% -> 0.088315111 | P58: =Q58+0.25% -> 0.085815111 | Q58: 0.083315111 | R58: =Q58-0.25% -> 0.080815111 | S58: =R58-0.25% -> 0.078315111
N59: =N60-0.25% -> 0.02 | O59: 1116959.9 | P59: 1148573.2 | Q59: 1182389.7 | R59: 1218674.7 | S59: 1257739
N60: =N61-0.25% -> 0.0225 | O60: 1138364.8 | P60: 1171864 | Q60: 1207809.4 | R60: 1246508.8 | S60: 1288325.1
...

Sheet WACC
B2: WACC
B4: WACC = % of equity x cost of equity + % of debt x cost of debt x (1 - Tax Rate)
B5: Cost of equity = Risk free rate + Beta x Market Risk Premium
A7: x | B7: WACC
B8: Market Cap | F8: =Comps!F12*Shares!E14 -> 2029800.4
B9: % of Equity | F9: =F8/$F$20 -> 0.97367042
B10: Cost of Equity | F10: =F11+F12*F13 -> 0.0845688
B11: Risk Free Rate | F11: 0.03909
B12: Beta | F12: =E33 -> 1.1201675
B13: Market Risk Premium | F13: 0.0406
B15: Debt | F15: 54889
B16: % of Debt | F16: =F15/$F$20 -> 0.026329582
B17: Cost of Debt | F17: =1233*2/F15 -> 0.044927035
B18: Tax Rate | F18: ='Operating Model'!L52 -> 0.1774763
B20: Total | F20: =F8+F15 -> 2084689.4
A22: x | B22: WACC | F22: =F9*F10+(F16*F17*(1-F18)) -> 0.083315111
B25: Beta
D27: Levered Beta | E27: Market Cap | F27: Net Debt | G27: Tax rate | I27: Unlevered Beta | K27: Levered beta / (1 + (1 - tax rate) * (Debt / Equity)
B28: AAPL | D28: 0.99 | E28: =Comps!D14 -> 3498463.5 | F28: =2994+12114+86196-25565-36236 -> 39503 | G28: 0.158 | I28: =(D28/(1+(1-G28)*(F28/E28))) -> 0.98067625 | K28: Unlevered Beta * (1 + (1-tax rate) * (Debt / Equity))
B29: MSFT | D29: 1.23 | E29: =Comps!D16 -> 3041094.8 | F29: =2249+42868-20840-57588 -> -33311 | G29: 0.19 | I29: =(D29/(1+(1-G29)*(F29/E29))) -> 1.2410108
B30: GOOGL | D30: 1.14 | E30: =Comps!D17 -> 2113086 | F30: =13253-24048-86868 -> -97663 | G30: 0.16 | I30: =(D30/(1+(1-G30)*(F30/E30))) -> 1.1860462
B32: Industry Average Unlevered Beta | E32: =AVERAGE(I28:I30) -> 1.1359111
B33: Amazon (AMZN) Levered Beta | E33: =E32*(1+(1-F18)*((Consolidated!K43-Consolidated!K42)/F8)) -> 1.1201675
B35: NOT IN USE
B36: NVDA | D36: 2.98 | E36: =Comps!D15 -> 3270094.3 | F36: =8461-8563-26237 -> -26339 | G36: 0.137 | I36: =(D36/(1+(1-G36)*(F36/E36))) -> 3.0008591

Sheet Shares
B2: Diluted Share Count Calculation
A4: x | B4: Fully Diluted Shares
B6: Current Stock Price | E6: =Comps!F12 -> 186.63
B7: Basic shares outstanding (latest filing) | E7: 10495.567
B8: In-the-money exercisable options | E8: =E30 -> 0
B9: Total proceeds ($mm) | E9: =SUMPRODUCT(D19:D28,E19:E28) -> 0
B10: Total shares repurchased (mm) | E10: =E9/E6 -> 0
B11: Net dilutive options | E11: =E8-E10 -> 0
B12: Dilutive impact of shares from other securities | E12: =380.5+E39 -> 380.5
B14: Net diluted shares outstanding | E14: =E7+E11+E12 -> 10876.067
A16: x | B16: Options outstanding
C18: Outstanding | D18: Exercise price | E18: Dilutive Shares
B19: 1 | E19: =IF(D19<$E$6,C19) -> 0
B20: =B19+1 -> 2 | E20: =IF(D20<$E$6,C20) -> 0
B21: =B20+1 -> 3 | E21: =IF(D21<$E$6,C21) -> 0
B22: =B21+1 -> 4 | E22: =IF(D22<$E$6,C22) -> 0
B23: =B22+1 -> 5 | E23: =IF(D23<$E$6,C23) -> 0
B24: =B23+1 -> 6 | E24: =IF(D24<$E$6,C24) -> 0
B25: =B24+1 -> 7 | E25: =IF(D25<$E$6,C25) -> 0
B26: =B25+1 -> 8 | E26: =IF(D26<$E$6,C26) -> 0
B27: =B26+1 -> 9 | E27: =IF(D27<$E$6,C27) -> 0
B28: =B27+1 -> 10 | E28: =IF(D28<$E$6,C28) -> 0
A30: x | B30: Total | E30: =SUM(E19:E28) -> 0
A32: x | B32: Convertible Bonds
B34: Principal Outstanding | E34: 0
B35: Conversion Ratio | E35: 0
B36: Conversion Price | E36: =IFERROR(E34/E37,0) -> 0
B37: Convertible Common Shares | E37: =E34*E35/1000 -> 0
B39: Dilutive impact of convertible securities | E39: =IF(E6>E36,E37,0) -> 0
A40: x | B40: Elimination of liability from net debt | E40: =-E34 -> 0

Sheet Comps
AH1: x
B2: rareliquid - Comps Tables | E2: STRICTLY CONFIDENTIAL | H2: STRICTLY CONFIDENTIAL | K2: STRICTLY CONFIDENTIAL | O2: STRICTLY CONFIDENTIAL | P2: STRICTLY CONFIDENTIAL | AH2: x
AH3: x
B4: Date | C4: 45596 | E4: PLEASE DO NOT SEND THIS DATA TO ANYONE ELSE. RARELIQUID HAS A DISTRIBUTION AGREEMENT WITH FACTSET THAT DOES NOT ALLOW FOR THIS DATA TO BE DISTRIBUTED TO PARTIES WHO ARE NOT CLIENTS OF RARELIQUID. | AH4: x
B5: Currency | C5: USD
B7: 1 | C7: 2 | D7: 7 | E7: 12 | F7: 14 | G7: 15 | H7: 16 | I7: 17 | J7: 21 | K7: 22 | L7: 23 | N7: 44 | O7: 45 | P7: 46 | Q7: 47 | R7: 48 | S7: 49 | T7: 51 | U7: 52 | V7: 55 | W7: 56 | Y7: 61 | Z7: 62 | AA7: 63 | AB7: 64 | AC7: 68 | AD7: 69 | AE7: 73 | AF7: 74 | AH7: 86 | AI7: 87 | AJ7: 88 | AK7: 89 | AL7: 90 | AM7: 91 | AN7: 92 | AO7: 93 | AP7: 94
J8: 1-Month | K8: 3-Month | L8: 6-Month | Y8: Trading Multiples | AH8: Premium (Discount) to Historical Multiples | AK8: Premium (Discount) to Historical Multiples
D9: Market | E9: Enterprise | F9: Current | G9: 52-Wk | H9: 52-Wk | I9: %-52-Wk | J9: Price | K9: Price | L9: Price | N9: Revenue Growth | P9: Gross Margin | R9: EBIT Margin | T9: EBITDA Margin | V9: Profit Margin | Y9: EV / Revenue | AA9: EV / Gross Profit | AC9: EV / EBITDA | AE9: P / E | AH9: EV / NTM Revenue | AK9: EV / NTM EBITDA | AN9: EV / NTM Revenue
B10: Ticker | C10: Company Name | D10: Cap | E10: Value | F10: Price | G10: Low | H10: High | I10: High | J10: Change | K10: Change | L10: Change | N10: '23-'24 | O10: '24-'25 | P10: '24 | Q10: '25 | R10: '24 | S10: '25 | T10: '24 | U10: '25 | V10: '24 | W10: '25 | Y10: '24 | Z10: '25 | AA10: '24 | AB10: '25 | AC10: '24 | AD10: '25 | AE10: '24 | AF10: '25 | AH10: 1 year | AI10: 2 year | AJ10: 5 year | AK10: 1 year | AL10: 2 year | AM10: 5 year | AN10: 1 year | AO10: 2 year | AP10: 5 year
B12: AMZN | C12: Amazon.com, Inc. | D12: 1950239.9 | E12: 2050701 | F12: 186.63 | G12: 137 | H12: 200 | I12: 0.93315 | J12: 0.0081024145 | K12: 0.1115545 | L12: 0.002255518 | N12: 0.10556782 | O12: 0.10836636 | P12: 0.48690849 | Q12: 0.49449717 | R12: 0.098186479 | S12: 0.10870708 | T12: 0.21575693 | U12: 0.22657967 | V12: 0.079745304 | W12: 0.089845347 | Y12: 3.2270934 | Z12: 2.9115764 | AA12: 6.6277205 | AB12: 5.8879537 | AC12: 14.957079 | AD12: 12.850122 | AE12: 38.485054 | AF12: 30.818982 | AH12: 0.034259309 | AI12: 0.18986178 | AJ12: 0.022352047 | AK12: -0.042203398 | AL12: -0.029173234 | AM12: -0.26994857 | AN12: -0.15208275 | AO12: -0.30795616 | AP12: -0.4660904
B14: AAPL | C14: Apple Inc. | D14: 3498463.5 | E14: 3571118.1 | F14: 227.6 | G14: 165 | H14: 236.48 | I14: 0.96244926 | J14: 0.0061447328 | K14: 0.035204221 | L14: 0.24113862 | N14: 0.032698817 | O14: 0.070976935 | P14: 0.4624129 | Q14: 0.46654666 | R14: 0.31514666 | S14: 0.31956192 | T14: 0.34404919 | U14: 0.34658305 | V14: 0.2648221 | W14: 0.26728849 | Y14: 8.9654921 | Z14: 8.3713214 | AA14: 19.388499 | AB14: 17.94316 | AC14: 26.058751 | AD14: 24.153869 | AE14: 33.165996 | AF14: 30.682229 | AH14: 0.093196205 | AI14: 0.17427316 | AJ14: 0.27537621 | AK14: 0.07314992 | AL14: 0.12801564 | AM14: 0.16633972 | AN14: 0.095294365 | AO14: 0.14981597 | AP14: 0.18774118
B15: NVDA | C15: NVIDIA Corporation | D15: 3270094.3 | E15: 3437411.1 | F15: 134.415 | G15: 42.325 | H15: 143.71 | I15: 0.93532113 | J15: 0.14884615 | K15: 0.25305304 | L15: 0.51386996 | N15: 1.1630697 | O15: 0.46692171 | P15: 0.75424998 | Q15: 0.73506262 | R15: 0.6514902 | S15: 0.64783948 | T15: 0.65100437 | U15: 0.65597725 | V15: 0.53367286 | W15: 0.52703373 | Y15: 28.596319 | Z15: 19.4941 | AA15: 37.913583 | AB15: 26.520326 | AC15: 43.926462 | AD15: 29.717647 | AE15: 50.975773 | AF15: 35.18792 | AH15: 0.11529528 | AI15: 0.11811153 | AJ15: 0.22305335 | AK15: 0.081279269 | AL15: -0.05102487 | AM15: -0.070236663 | AN15: 0.1137955 | AO15: -0.042586061 | AP15: -0.090566199
B16: MSFT | C16: Microsoft Corporation | D16: 3041094.8 | E16: 3077540.8 | F16: 410.9321 | G16: 346.07 | H16: 467.56 | I16: 0.87888635 | J16: -0.023194989 | K16: 0.0059783593 | L16: 0.010505336 | N16: 0.15412961 | O16: 0.13777538 | P16: 0.69015045 | Q16: 0.67981097 | R16: 0.44031237 | S16: 0.44142773 | T16: 0.53793368 | U16: 0.54264366 | V16: 0.35671652 | W16: 0.35203354 | Y16: 11.716811 | Z16: 10.298 | AA16: 16.977183 | AB16: 15.148329 | AC16: 21.781144 | AD16: 18.977463 | AE16: 32.457296 | AF16: 28.906465 | AH16: -0.063622978 | AI16: 0.025945926 | AJ16: 0.066964454 | AK16: -0.08279612 | AL16: -0.023123917 | AM16: -0.023486048 | AN16: -0.063377445 | AO16: 0.0088863118 | AP16: 0.0054335497
B17: GOOGL | C17: Alphabet Inc. Class A | D17: 2113086 | E17: 2062690.7 | F17: 172.11 | G17: 126.45 | H17: 191.18 | I17: 0.90025107 | J17: 0.030660519 | K17: 0.032701308 | L17: 0.029119828 | N17: 0.13873231 | O17: 0.11535582 | P17: 0.58154133 | Q17: 0.58264604 | R17: 0.31784763 | S17: 0.32286396 | T17: 0.4300163 | U17: 0.44079433 | V17: 0.28290838 | W17: 0.28090991 | Y17: 5.8972842 | Z17: 5.2873568 | AA17: 10.140782 | AB17: 9.0747323 | AC17: 13.714094 | AD17: 11.995065 | AE17: 21.354495 | AF17: 19.282112 | AH17: 0.01613349 | AI17: 0.11593366 | AJ17: 0.067996633 | AK17: -0.027189818 | AL17: 0.039250714 | AM17: -0.054470331 | AN17: -0.055307977 | AO17: -0.024751141 | AP17: -0.15707143
B18: META | C18: Meta Platforms Inc Class A | D18: 1435256.6 | E18: 1453765 | F18: 567.58 | G18: 310.87 | H18: 595.94 | I18: 0.95241132 | J18: -0.015421444 | K18: 0.1627402 | L18: 0.2558191 | N18: 0.20279922 | O18: 0.14155459 | P18: 0.81211077 | Q18: 0.80228957 | R18: 0.40325964 | S18: 0.40729769 | T18: 0.60446985 | U18: 0.61776352 | V18: 0.35424703 | W18: 0.34605176 | Y18: 8.9594775 | Z18: 7.848488 | AA18: 11.032334 | AB18: 9.7826126 | AC18: 14.822042 | AD18: 12.70468 | AE18: 24.969613 | AF18: 22.39135 | AH18: 0.10461481 | AI18: 0.37860303 | AJ18: 0.34503578 | AK18: 0.050646165 | AL18: 0.22447458 | AM18: 0.11596556 | AN18: 0.021761018 | AO18: 0.12104367 | AP18: 0.069749468
B19: WMT | C19: Walmart Inc. | D19: 662311.56 | E19: 716555.59 | F19: 82.395 | G19: 50.286613 | H19: 83.27 | I19: 0.98949201 | J19: 0.013842746 | K19: 0.20354952 | L19: 0.37738215 | N19: 0.047812365 | O19: 0.041491174 | P19: 0.23854433 | Q19: 0.24309602 | R19: 0.043137057 | S19: 0.045481754 | T19: 0.062107704 | U19: 0.064795392 | V19: 0.028997926 | W19: 0.030852765 | Y19: 1.0602269 | Z19: 1.0179893 | AA19: 4.4445695 | AB19: 4.1876016 | AC19: 17.070779 | AD19: 15.710828 | AE19: 33.794367 | AF19: 30.497312 | AH19: 0.20286388 | AI19: 0.28907741 | AJ19: 0.30729407 | AK19: 0.16978745 | AL19: 0.22623617 | AM19: 0.26224722 | AN19: 0.19590017 | AO19: 0.26318834 | AP19: 0.31441505
B21: Mean | I21: 0.93646852 | J21: 0.024140019 | K21: 0.11496873 | L21: 0.20429864 | N21: 0.28987368 | O21: 0.16234593 | P21: 0.58983496 | Q21: 0.58490865 | R21: 0.36186559 | S21: 0.36407876 | T21: 0.43826352 | U21: 0.44475954 | V21: 0.3035608 | W21: 0.30069503 | Y21: 10.865935 | Z21: 8.7195426 | AA21: 16.649492 | AB21: 13.776127 | AC21: 22.895545 | AD21: 18.876592 | AE21: 32.786257 | AF21: 27.824565 | AH21: 0.078080115 | AI21: 0.18365745 | AJ21: 0.21428675 | AK21: 0.044146144 | AL21: 0.090638053 | AM21: 0.06605991 | AN21: 0.051344272 | AO21: 0.079266182 | AP21: 0.054950268
A22: x | B22: Median | I22: 0.94386622 | J22: 0.0081024145 | K22: 0.1115545 | L22: 0.24113862 | N22: 0.14643096 | O22: 0.1265656 | P22: 0.63584589 | Q22: 0.6312285 | R22: 0.36055364 | S22: 0.36508083 | T22: 0.48397499 | U22: 0.491719 | V22: 0.3185777 | W22: 0.31348084 | Y22: 8.9624848 | Z22: 8.1099047 | AA22: 14.004759 | AB22: 12.465471 | AC22: 19.425961 | AD22: 17.344146 | AE22: 32.811646 | AF22: 29.701888 | AH22: 0.098905507 | AI22: 0.14619235 | AJ22: 0.24921478 | AK22: 0.061898042 | AL22: 0.083633178 | AM22: 0.046239755 | AN22: 0.058527692 | AO22: 0.064964991 | AP22: 0.037591509

Sheet FS>>>

Sheet Segments
A1: AMZN-US
A2: Geographic Segments (M)
B3: CY '14 | C3: CY '15 | D3: CY '16 | E3: CY '17 | F3: CY '18 | G3: CY '19 | H3: CY '20 | I3: CY '21 | J3: CY '22 | K3: CY '23 | L3: CY '24E | M3: CY '25E | N3: CY '26E | O3: CY '27E | P3: CY '28E | Q3: CY '29E
B4: Dec '14 | C4: Dec '15 | D4: Dec '16 | E4: Dec '17 | F4: Dec '18 | G4: Dec '19 | H4: Dec '20 | I4: Dec '21 | J4: Dec '22 | K4: Dec '23 | L4: Dec '24E | M4: Dec '25E | N4: Dec '26E | O4: Dec '27E | P4: Dec '28E | Q4: Dec '29E
A5: Sales | B5: 88988 | C5: 107006 | D5: 135987 | E5: 177866 | F5: 232887 | G5: 280522 | H5: 386064 | I5: 469822 | J5: 513983 | K5: 574785 | L5: 635548 | M5: 704509 | N5: 779688 | O5: 858282 | P5: 942468 | Q5: 1029190
A6: North America | B6: 55469 | C6: 63708 | D6: 79785 | E6: 106110 | F6: 141366 | G6: 170773 | H6: 236282 | I6: 279833 | J6: 315880 | K6: 352828 | L6: 386647 | M6: 423461 | N6: 461471 | O6: 497416 | P6: 546306 | Q6: 590847
A7: - NA Other | B7: - | C7: - | D7: 1318 | E7: - | F7: - | G7: - | H7: - | I7: - | J7: 4247 | K7: - | L7: 5380 | M7: - | N7: - | O7: - | P7: - | Q7: -
A8: International | B8: 33519 | C8: 35418 | D8: 43983 | E8: 54297 | F8: 65866 | G8: 74723 | H8: 104412 | I8: 127787 | J8: 118007 | K8: 131200 | L8: 141444 | M8: 154680 | N8: 171709 | O8: 192631 | P8: 199416 | Q8: 215930
A9: AWS-Geo | B9: - | C9: 7880 | D9: 12219 | E9: 17459 | F9: 25655 | G9: 35026 | H9: 45370 | I9: 62202 | J9: 80096 | K9: 90757 | L9: 107555 | M9: 127628 | N9: 151647 | O9: 176580 | P9: 208724 | Q9: 249139
A11: Operating Income | B11: 178 | C11: 2233 | D11: 4186 | E11: 4106 | F11: 12421 | G11: 14541 | H11: 22899 | I11: 24879 | J11: 12248 | K11: 36852 | L11: 62364.9 | M11: 76519.4 | N11: 95065 | O11: 119029 | P11: 143146 | Q11: 174540
A12: North America | B12: 2105 | C12: 2751 | D12: 4099 | E12: 2837 | F12: 7267 | G12: 7033 | H12: 8651 | I12: 7271 | J12: -2847 | K12: 14877 | L12: 23233.5 | M12: 31059.3 | N12: 34190 | O12: - | P12: - | Q12: -
A13: - NA Media | B13: - | C13: - | D13: - | E13: - | F13: - | G13: - | H13: - | I13: - | J13: -2847 | K13: - | L13: - | M13: - | N13: - | O13: - | P13: - | Q13: -
A14: International | B14: -297 | C14: -91 | D14: -477 | E14: -3062 | F14: -2142 | G14: -1693 | H14: 717 | I14: -924 | J14: -7746 | K14: -2656 | L14: 1765.17 | M14: 3899.91 | N14: 9726 | O14: - | P14: - | Q14: -
A15: AWS-Geo | B15: - | C15: 1863 | D15: 3706 | E15: 4331 | F15: 7296 | G15: 9201 | H15: 13531 | I15: 18532 | J15: 22841 | K15: 24631 | L15: 37271.5 | M15: 42816.2 | N15: 53907.1 | O15: 70418.5 | P15: 85067.5 | Q15: 102298
A16: WFM- Geo | B16: - | C16: - | D16: - | E16: - | F16: - | G16: - | H16: - | I16: 495.175 | J16: 568.89 | K16: - | L16: - | M16: - | N16: - | O16: - | P16: - | Q16: -
A18: EBITDA | B18: 6553 | C18: 10805 | D18: 15440 | E18: 20007 | F18: 33476 | G18: 43245 | H18: 57284 | I18: 71994 | J18: 73836 | K18: 109538 | L18: 137679 | M18: 159786 | N18: 184965 | O18: 217623 | P18: 248736 | Q18: 289356
A19: North America | B19: - | C19: - | D19: - | E19: 7463 | F19: 13492 | G19: 16504 | H19: 17413 | I19: 22762 | J19: 17894 | K19: 41189 | L19: 47377 | M19: 53874 | N19: - | O19: - | P19: - | Q19: -
A20: International | B20: - | C20: - | D20: - | E20: 1945 | F20: - | G20: 5921 | H20: 7269 | I20: 14485 | J20: 14198 | K20: 16832 | L20: 25226 | M20: 28198 | N20: - | O20: - | P20: - | Q20: -
A21: AWS-Geo | B21: - | C21: - | D21: - | E21: 9128 | F21: 14189 | G21: 18239.6 | H21: 22953.5 | I21: 31239 | J21: 37506 | K21: 46916 | L21: 65410.5 | M21: 76791.5 | N21: 99377 | O21: 118602 | P21: 140497 | Q21: 165221

Sheet IS
A1: Amazon.com, Inc. (AMZN)
A2: $172.12
A5: Amazon.com, Inc.
A6: AMZN 023135106 2000019 NASDAQ Common stock
A7: Source: FactSet Fundamentals
B8: DEC '14 | C8: DEC '15 | D8: DEC '16 | E8: DEC '17 | F8: DEC '18 | G8: DEC '19 | H8: DEC '20 | I8: DEC '21 | J8: DEC '22 | K8: DEC '23 | L8: JUN '24
L9: LTM
A10: Sales | B10: 88988 | C10: 107006 | D10: 135987 | E10: 177866 | F10: 232887 | G10: 280522 | H10: 386064 | I10: 469822 | J10: 513983 | K10: 574785 | L10: 604334
A11: Cost of Goods Sold (COGS) incl. D&A | B11: 62752 | C11: 71651 | D11: 88265 | E11: 111934 | F11: 139156 | G11: 165536 | H11: 233307 | I11: 272344 | J11: 288831 | K11: 304739 | L11: 313993
